Workbook

Sheet Prospectos
A1: ID | B1: 🔥 Prioridad | C1: Score | D1: Nombre | E1: Especialidad | F1: Ciudad / Barrio | G1: Teléfono | H1: Instagram | I1: WhatsApp (link) | J1: URL Perfil | K1: Notas iniciales | L1: 📞 Fecha Llamada 1 | M1: Estado Llamada 1 | N1: 📲 Fecha Demo enviada | O1: 👀 Probó la demo? | P1: 🚦 Señal de interés | Q1: 📞 Fecha Llamada 2 | R1: 💰 Cerrado? | S1: Notas
A2: 1 | B2: 🔥 HOT | C2: 8 | D2: Lic. María Constanza Alaye | E2: Psicología clínica / EMDR | F2: Córdoba Capital | G2: 3512308121 | I2: https://wa.me/543512308121 | J2: https://www.doctoraliar.com/maria-constanza-alaye/psicologo/cordoba-capital | K2: 114 reseñas Doctoralia. Red Cales.
A3: 2 | B3: 🔥 HOT | C3: 8 | D3: Lic. Vilma Barrios | E3: Psicoanálisis / Clínica | F3: Córdoba Capital | G3: 3512308121 | I3: https://wa.me/543512308121 | J3: https://www.doctoraliar.com/vilma-barrios/psicologo/cordoba-capital | K3: 48 reseñas. Red Cales.
A4: 3 | B4: 🔥 HOT | C4: 8 | D4: Lic. Araceli Mañanes | E4: Psicología clínica | F4: Córdoba Capital | G4: 3512308121 | I4: https://wa.me/543512308121 | J4: https://www.doctoraliar.com/araceli-mananes/psicologo/cordoba-capital | K4: 38 reseñas. Red Cales.
A5: 4 | B5: 🔥 HOT | C5: 8 | D5: Lic. Silvina Jimenez | E5: Psicoanálisis / Clínica | F5: Córdoba Capital | G5: 3512308121 | I5: https://wa.me/543512308121 | J5: https://www.doctoraliar.com/silvina-jimenez/psicologo/cordoba-capital | K5: 36 reseñas. Red Cales.
A6: 5 | B6: 🔥 HOT | C6: 8 | D6: Lic. Magalí Langone | E6: Gestalt / Clínica | F6: Córdoba Capital | G6: 3512308121 | I6: https://wa.me/543512308121 | J6: https://www.doctoraliar.com/magali-langone/psicologo/cordoba-capital | K6: 26 reseñas. Red Cales.
A7: 6 | B7: ⚡ WARM | C7: 7 | D7: Lic. Daniela Agüero | E7: Psicoanálisis | F7: Córdoba Capital | G7: 3512308121 | I7: https://wa.me/543512308121 | J7: https://www.doctoraliar.com/daniela-aguero/psicologo/cordoba-capital | K7: 23 reseñas. Red Cales.
A8: 7 | B8: ⚡ WARM | C8: 7 | D8: Lic. Gonzalo Shalom | E8: Psicología clínica (UBA) | F8: Palermo, CABA | J8: https://www.mundopsicologos.com.ar/centros/lic-gonzalo-shalom | K8: MN 70833. Presencial y online.
A9: 8 | B9: ⚡ WARM | C9: 7 | D9: Lic. Martina Michelini | E9: TCC / Autoestima | F9: Palermo, CABA | J9: https://www.mundopsicologos.com.ar/centros/lic-martina-michelini | K9: Presencial y online.
A10: 9 | B10: ⚡ WARM | C10: 7 | D10: Lic. Carolina Ramos | E10: TCC / Terapia pareja | F10: Belgrano, CABA | J10: https://www.mundopsicologos.com.ar/centros/lic-carolina-ramos | K10: Jose Hernandez 1955. Online.
A11: 10 | B11: ⚡ WARM | C11: 6 | D11: Lic. Daniela Sommer | E11: Psicología clínica | F11: Cerro de las Rosas, CBA | G11: 3512308121 | I11: https://wa.me/543512308121 | J11: https://cales.com.ar/profesional/lic-daniela-soledad-sommer/ | K11: Red Cales WA
A12: 11 | B12: ⚡ WARM | C12: 6 | D12: Lic. Martina Nobile Giusto | E12: Psicología clínica | F12: Cerro de las Rosas, CBA | G12: 3512308121 | I12: https://wa.me/543512308121 | J12: https://cales.com.ar/profesional/lic-martina-nobile-giusto/ | K12: Red Cales WA
A13: 12 | B13: ⚡ WARM | C13: 6 | D13: Lic. Silvana Oviedo | E13: Psicología clínica | F13: Cerro de las Rosas, CBA | G13: 3512308121 | I13: https://wa.me/543512308121 | J13: https://cales.com.ar/profesional/lic-silvana-oviedo/ | K13: Red Cales WA
A14: 13 | B14: ⚡ WARM | C14: 6 | D14: Lic. Martin Diego Garro | E14: Psicología clínica | F14: Nueva Córdoba | G14: 3512308121 | I14: https://wa.me/543512308121 | J14: https://cales.com.ar/profesional/lic-martin-diego-garro/ | K14: Red Cales WA
A15: 14 | B15: ⚡ WARM | C15: 6 | D15: Lic. Carla Sigifredo | E15: Psicología clínica | F15: Nueva Córdoba / Alberdi | G15: 3512308121 | I15: https://wa.me/543512308121 | J15: https://cales.com.ar/profesional/lic-carla-sigifredo/ | K15: Red Cales WA
A16: 15 | B16: ⚡ WARM | C16: 6 | D16: Lic. Fabiana Paolini | E16: Psicología clínica | F16: Alberdi, Córdoba | G16: 3512308121 | I16: https://wa.me/543512308121 | J16: https://cales.com.ar/profesional/lic-fabiana-maria-paolini/ | K16: Red Cales WA
A17: 16 | B17: ⚡ WARM | C17: 6 | D17: Lic. Florencia Cárdenas | E17: Psicología clínica | F17: General Paz, Córdoba | G17: 3512308121 | I17: https://wa.me/543512308121 | J17: https://cales.com.ar/profesional/lic-florencia-cardenas/ | K17: Red Cales WA
A18: 17 | B18: ⚡ WARM | C18: 6 | D18: Lic. Valeria Pinotti | E18: Psicología clínica | F18: Córdoba Capital Centro | G18: 3512308121 | I18: https://wa.me/543512308121 | J18: https://cales.com.ar/profesional/lic-valeria-pinotti/ | K18: Red Cales WA
A19: 18 | B19: ⚡ WARM | C19: 6 | D19: Lic. Verónica Martinez | E19: Psicología clínica | F19: Córdoba Capital Centro | G19: 3512308121 | I19: https://wa.me/543512308121 | J19: https://cales.com.ar/profesional/lic-martinez-veronica-andrea/ | K19: Red Cales WA
A20: 19 | B20: ⚡ WARM | C20: 6 | D20: Estrin Silvia Noemi | E20: Ansiedad / Terapia pareja | F20: Palermo, CABA | J20: https://www.mundopsicologos.com.ar/centros/estrin-silvia-noemi | K20: Gurruchaga 506. Turnos online.
A21: 20 | B21: ⚡ WARM | C21: 6 | D21: Lic. Marcela Maidana | E21: Ansiedad / Pánico | F21: Belgrano, CABA | J21: https://www.mundopsicologos.com.ar/centros/lic-marcela-maidana | K21: Roosevelt 2400. Online.
A22: 21 | B22: ⚡ WARM | C22: 5 | D22: Eugenia Duarte | E22: Gestalt / Clínica | F22: Córdoba Capital | J22: https://psicologa.com.ar/ | K22: Online + presencial. 23 años exp.
A23: 22 | B23: ⚡ WARM | C23: 5 | D23: Lic. Antonella Galanti | E23: TCC / Terapias contextuales | F23: Recoleta/Palermo, CABA | J23: https://www.doctoraliar.com/antonella-galanti/psicologo/capital-federal | K23: 77 reseñas. Av. Libertador 1428.
A24: 23 | B24: ⚡ WARM | C24: 5 | D24: Lic. Janina Salatti | E24: Psicología laboral / clínica | F24: Palermo, CABA | J24: https://www.doctoraliar.com/janina-salatti/psicologo/rio-gallegos | K24: 79 reseñas. Paraguay 3042.
A25: 24 | B25: ⚡ WARM | C25: 5 | D25: Lic. Guido Pazos | E25: TCC / Clínica | F25: Palermo, CABA | J25: https://www.mundopsicologos.com.ar/centros/lic-guido-pazos | K25: Aráoz 2268.
A26: 25 | B26: ⚡ WARM | C26: 5 | D26: Lic. Florencia Larrarte | E26: TCC / Terapia pareja | F26: Recoleta, CABA | J26: https://www.mundopsicologos.com.ar/centros/lic-florencia-larrarte | K26: Gallo 1071.
A27: 26 | B27: ⚡ WARM | C27: 5 | D27: Gustavo Rimoli | E27: TCC / Clínica | F27: Recoleta, CABA | J27: https://www.mundopsicologos.com.ar/centros/gustavo-rimoli | K27: Las Heras 2050.
A28: 27 | B28: ⚡ WARM | C28: 5 | D28: María Paula de Veyga | E28: TCC / Psic. infantil | F28: Recoleta, CABA | J28: https://www.mundopsicologos.com.ar/centros/lic-maria-paula-de-veyga | K28: Austria 2122.
A29: 28 | B29: ⚡ WARM | C29: 5 | D29: Bárbara Ballesteros | E29: TCC / Ansiedad | F29: Palermo/Recoleta, CABA | J29: https://www.mundopsicologos.com.ar/centros/barbara-ballesteros | K29: Av. Santa Fe y Callao. $42k.
A30: 29 | B30: ⚡ WARM | C30: 5 | D30: Lic. Jonatan Sallustio | E30: TCC / Psicoanálisis | F30: Belgrano, CABA | J30: https://www.doctoraliar.com/jonatan-sallustio/psicologo-psicoanalista/capital-federal | K30: 75 reseñas. Av. Melián 2067.
A31: 30 | B31: ⚡ WARM | C31: 5 | D31: Lic. María Sol Cátera | E31: Psicología clínica | F31: Belgrano, CABA | J31: https://www.doctoraliar.com/maria-sol-catera/psicologo/capital-federal | K31: 46 reseñas. José Hernández 2729.
... A37: 36 | B37: ⚡ WARM | C37: 5 | D37: Lic. Sandra Gundin | E37: Terapia familiar / Clínica | F37: Belgrano, CABA | J37: https://www.mundopsicologos.com.ar/centros/lic-sandra-gundin | K37: La Pampa 2477.
A38: 37 | B38: 🥶 COLD | C38: 4 | D38: Lic. Cecilia A. Pegoraro | E38: Psicología clínica | F38: Córdoba Capital | G38: 0351 152832844 | I38: https://wa.me/54351152832844 | K38: MP 7601. Tel propio.
A39: 38 | B39: 🥶 COLD | C39: 4 | D39: Dra. Maria Alejandra Moisello | E39: Nutricionista | F39: Palermo, CABA | J39: https://www.doctoraliar.com/maria-alejandra-moisello/nutricionista/capital-federal | K39: 205 reseñas Doctoralia. Paraguay 2468 P2B.
A40: 39 | B40: 🥶 COLD | C40: 4 | D40: Lic. Margarita Grundnig | E40: Nutrición / Coaching nutric. | F40: Palermo-Botánico, CABA | J40: https://www.doctoraliar.com/margarita-grundnig/nutricionista/capital-federal | K40: 36 reseñas. Armenia 2387.
A41: 40 | B41: 🥶 COLD | C41: 4 | D41: Dra. Cecilia Trujillo | E41: Nutrición / Medicina integral. | F41: Palermo, CABA | J41: https://www.doctoraliar.com/cecilia-trujillo/medico-general-y-familiar-nutricionista/capital-federal | K41: 16 reseñas. Pueyrredón 1705.
A42: 41 | B42: 🥶 COLD | C42: 4 | D42: Lic. Celeste Diaz | E42: Psicología forense / Ansiedad | F42: Palermo, CABA | J42: https://www.doctoraliar.com/celeste-diaz/psicologo/benavidez | K42: 51 reseñas. Av. Santa Fe.
A43: 42 | B43: 🥶 COLD | C43: 4 | D43: Karina Matzkin | E43: Ansiedad / Depresión | F43: Palermo, CABA | J43: https://www.mundopsicologos.com.ar/centros/karina-matzkin | K43: Paraguay 3636.
A44: 43 | B44: 🥶 COLD | C44: 4 | D44: Lic. Lautaro Cisneros | E44: Ansiedad / Terapia pareja | F44: Palermo, CABA | J44: https://www.mundopsicologos.com.ar/centros/lic-lautaro-cisneros | K44: Paraguay 4176.
A45: 44 | B45: 🥶 COLD | C45: 4 | D45: Gabriela Fernández Ortiz | E45: Ansiedad / Psic. infantil | F45: Palermo, CABA | J45: https://www.mundopsicologos.com.ar/centros/gabriela-fernandez-ortiz | K45: Mansilla 3333.
...

Sheet 📊 Dashboard
A1: 📊 LUMIO CRM — DASHBOARD
A2: Total leads | B2: =COUNTA(Prospectos!D:D)-1
A3: Llamadas realizadas | B3: =COUNTA(Prospectos!L:L)-1
A4: Demos enviadas | B4: =COUNTA(Prospectos!N:N)-1
A5: Cerrados 💰 | B5: =COUNTIF(Prospectos!R:R,"Sí")
A6: Tasa demo | B6: =IFERROR(B4/B3,0)
A7: Tasa cierre | B7: =IFERROR(B5/B4,0)
A8: Setup cobrado (USD) | B8: =B5*200
A9: MRR comprometido | B9: =B5*99
A11: — Por Ciudad —
A12: Palermo, CABA | B12: =COUNTIF(Prospectos!F:F,"*Palermo*")
A13: Recoleta, CABA | B13: =COUNTIF(Prospectos!F:F,"*Recoleta*")
A14: Belgrano, CABA | B14: =COUNTIF(Prospectos!F:F,"*Belgrano*")
A15: Córdoba Capital | B15: =COUNTIF(Prospectos!F:F,"*Córdoba Capital*")
A16: Nueva Córdoba | B16: =COUNTIF(Prospectos!F:F,"*Nueva Córdoba*")
A17: Cerro de las Rosas, CBA | B17: =COUNTIF(Prospectos!F:F,"*Cerro de las Rosas*")
A19: — Por Prioridad —
A20: 🔥 HOT | B20: =COUNTIF(Prospectos!B:B,"*HOT*")
A21: ⚡ WARM | B21: =COUNTIF(Prospectos!B:B,"*WARM*")
A22: 🥶 COLD | B22: =COUNTIF(Prospectos!B:B,"*COLD*")

Sheet 🎙️ Guion + Mensajes
A1: 📞 GUION LLAMADA 1 (memorizar)
A3: APERTURA (8 seg):
A4: "Hola, ¿hablo con [consultorio]? Soy Fran de Lumio. Te robo 30 segundos y si no te interesa cortamos sin problema, ¿va?"
A6: GANCHO (15 seg):
A7: "Trabajamos con consultorios de psicología en Argentina automatizando atención por WhatsApp con IA. El bot toma turnos, confirma sesiones y reduce ausencias 50%. ¿Hoy en tu consultorio, quién responde los WhatsApp?"
A9: PIVOT a demo:
A10: "Mirá, lo mejor es que lo veas funcionando. Te paso un asistente en vivo para que lo pruebes como paciente. ¿A qué número te lo mando?"
A12: ────────────────────────────────────────────────────────────
A13: 📲 MENSAJE POST-LLAMADA (copiar y pegar)
A15: Hola [NOMBRE]! Soy Fran de Lumio, hablamos recién.
A16: Acá te dejo el asistente para que lo pruebes como paciente.
A17: 📲 3535109880
... A36: "Ya tengo Doctoralia" → "Eso te facilita. Pero Doctoralia no te atiende los WhatsApp ni confirma sesiones. ¿Cuántos pacientes te faltan sin avisar por semana?"

Sheet 📈 Métricas diarias
A1: Fecha | B1: Llamadas marcadas | C1: Atendieron | D1: Aceptaron demo | E1: Demos enviadas | F1: Llamada 2 hecha | G1: Cerrados | H1: Notas día
A2: 46153 | B2: 0 | C2: 0 | D2: 0 | E2: 0 | F2: 0 | G2: 0
A3: 46154 | B3: 0 | C3: 0 | D3: 0 | E3: 0 | F3: 0 | G3: 0
A4: 46155 | B4: 0 | C4: 0 | D4: 0 | E4: 0 | F4: 0 | G4: 0
A5: 46156 | B5: 0 | C5: 0 | D5: 0 | E5: 0 | F5: 0 | G5: 0
A6: 46157 | B6: 0 | C6: 0 | D6: 0 | E6: 0 | F6: 0 | G6: 0
A7: 46158 | B7: 0 | C7: 0 | D7: 0 | E7: 0 | F7: 0 | G7: 0
A8: 46159 | B8: 0 | C8: 0 | D8: 0 | E8: 0 | F8: 0 | G8: 0
A9: 46160 | B9: 0 | C9: 0 | D9: 0 | E9: 0 | F9: 0 | G9: 0
A10: 46161 | B10: 0 | C10: 0 | D10: 0 | E10: 0 | F10: 0 | G10: 0
A11: 46162 | B11: 0 | C11: 0 | D11: 0 | E11: 0 | F11: 0 | G11: 0
A12: 46163 | B12: 0 | C12: 0 | D12: 0 | E12: 0 | F12: 0 | G12: 0
A13: 46164 | B13: 0 | C13: 0 | D13: 0 | E13: 0 | F13: 0 | G13: 0
... A15: 46166 | B15: 0 | C15: 0 | D15: 0 | E15: 0 | F15: 0 | G15: 0
A17: TOTALES | B17: =SUM(B2:B15) | C17: =SUM(C2:C15) | D17: =SUM(D2:D15) | E17: =SUM(E2:E15) | F17: =SUM(F2:F15) | G17: =SUM(G2:G15)
A18: Tasas | C18: =IFERROR(C17/B17,0) | D18: =IFERROR(D17/C17,0) | E18: =IFERROR(E17/D17,0) | G18: =IFERROR(G17/E17,0)

Sheet 📚 Cómo crecer el CRM
A1: 📚 CÓMO CRECER ESTE CRM DESDE EL CELU
A3: LISTA INICIAL: ~60 leads sembrados automáticamente.
A4: META: llegar a 300 leads en 1 semana.
A6: CÓMO AGREGAR LEADS DESDE EL CELU (10 min/día):
A8: 1. Abrí Instagram
A9: 2. Buscá hashtags: #psicologapalermo #psicologacordoba #nutricionistabuenosaires #psicologabsas
A10: 3. Por cada perfil interesante:
A11: • Copiá el @ del IG
A12: • Mirá si tiene WhatsApp en bio (anotá número)
A13: • Agregá UNA FILA al final de la hoja Prospectos
A14: • Mínimo: nombre + IG + ciudad
A15: 4. 10 perfiles por día = 70 nuevos leads/semana
... A34: HOT ≥8 | WARM 5-7 | COLD <5
